<mujoco model="kinova3">
  <actuator>
    <!-- Physical limits of the actuator. Pulled directly from datasheet. See pg 24 of:
         https://www.kinovarobotics.com/sites/default/files/UG-014_KINOVA_Gen3_Ultra_lightweight_robot_User_guide_EN_R06_0.pdf -->
    <motor ctrllimited="true" ctrlrange="-32.0 32.0" joint="Actuator1" name="torq_j1"/>
    <motor ctrllimited="true" ctrlrange="-32.0 32.0" joint="Actuator2" name="torq_j2"/>
    <motor ctrllimited="true" ctrlrange="-32.0 32.0" joint="Actuator3" name="torq_j3"/>
    <motor ctrllimited="true" ctrlrange="-32.0 32.0" joint="Actuator4" name="torq_j4"/>
    <motor ctrllimited="true" ctrlrange="-32.0 32.0" joint="Actuator5" name="torq_j5"/>
    <motor ctrllimited="true" ctrlrange="-13.0 13.0" joint="Actuator6" name="torq_j6"/>
    <motor ctrllimited="true" ctrlrange="-13.0 13.0" joint="Actuator7" name="torq_j7"/>
  </actuator>
  <asset>
    <mesh name="base_link" file="meshes/base_link.stl" />
    <mesh name="shoulder_link" file="meshes/shoulder_link.stl" />
    <mesh name="half_arm_1_link" file="meshes/half_arm_1_link.stl" />
    <mesh name="half_arm_2_link" file="meshes/half_arm_2_link.stl" />
    <mesh name="forearm_link" file="meshes/forearm_link.stl" />
    <mesh name="spherical_wrist_1_link" file="meshes/spherical_wrist_1_link.stl" />
    <mesh name="spherical_wrist_2_link" file="meshes/spherical_wrist_2_link.stl" />
    <mesh name="bracelet_with_vision_link" file="meshes/bracelet_with_vision_link.stl" />
  </asset>
  <worldbody>
    <body name="base" pos="0 0 0">
      <!-- robot view -->
      <camera mode="fixed" name="robotview" pos="1.0 0 0.4" quat="0.653 0.271 0.271 0.653"/>
      <inertial diaginertia="0 0 0" mass="1" pos="0 0 0" quat="1 0 0 0"/>
      <!-- mount attached here -->
      <geom type="mesh" contype="0" conaffinity="0" group="1" rgba="1 1 1 1" mesh="base_link" />
      <geom type="mesh" conaffinity="0" rgba="0.75294 0.75294 0.75294 1" mesh="base_link" name="base_collision" />
      <body name="shoulder_link" pos="0 0 0.15643" quat="-3.67321e-06 1 0 0">
        <inertial pos="-2.3e-05 -0.010364 -0.07336" quat="0.707051 0.0451246 -0.0453544 0.704263" mass="1.3773" diaginertia="0.00488868 0.00457 0.00135132" />
        <joint name="Actuator1" pos="0 0 0" axis="0 0 1" frictionloss="0.5217383101288284" damping="10.5" armature="8.03"/>
        <geom type="mesh" contype="0" conaffinity="0" group="1" rgba="1 1 1 1" name="s_visual" mesh="shoulder_link" />
        <geom type="mesh" conaffinity="0" rgba="0.75294 0.75294 0.75294 1" mesh="shoulder_link" name="s_collision"/>
        <body name="HalfArm1_Link" pos="0 0.005375 -0.12838" quat="0.707105 0.707108 0 0">
          <inertial pos="-4.4e-05 -0.09958 -0.013278" quat="0.482348 0.516286 -0.516862 0.483366" mass="1.1636" diaginertia="0.0113017 0.011088 0.00102532" />
          <joint name="Actuator2" pos="0 0 0" axis="0 0 1" limited="true" range="-2.41 2.41" frictionloss="0.5769579059927288" damping="7.406484581723072" armature="11.996202461530364"/>
          <geom type="mesh" contype="0" conaffinity="0" group="1" rgba="1 1 1 1" name="ha1_visual" mesh="half_arm_1_link" />
          <geom type="mesh" conaffinity="0" rgba="0.75294 0.75294 0.75294 1" mesh="half_arm_1_link" name="ha1_collision"/>
          <body name="HalfArm2_Link" pos="0 -0.21038 -0.006375" quat="0.707105 -0.707108 0 0">
            <inertial pos="-4.4e-05 -0.006641 -0.117892" quat="0.706144 0.0213722 -0.0209128 0.707437" mass="1.1636" diaginertia="0.0111633 0.010932 0.00100671" />
            <joint name="Actuator3" pos="0 0 0" axis="0 0 1" frictionloss="0.4213397946418778" damping="9.972763340817286" armature="9.002542786175152"/>
            <geom type="mesh" contype="0" conaffinity="0" group="1" rgba="1 1 1 1" name="ha2_visual" mesh="half_arm_2_link"/>
            <geom type="mesh" conaffinity="0" rgba="0.75294 0.75294 0.75294 1" mesh="half_arm_2_link" name="ha2_collision"/>
            <body name="forearm_link" pos="0 0.006375 -0.21038" quat="0.707105 0.707108 0 0">
              <inertial pos="-1.8e-05 -0.075478 -0.015006" quat="0.483678 0.515961 -0.515859 0.483455" mass="0.9302" diaginertia="0.00834839 0.008147 0.000598606" />
              <joint name="Actuator4" pos="0 0 0" axis="0 0 1" limited="true" range="-2.66 2.66" frictionloss="0.4945515376566732" damping="8.266795082250392" armature="11.580643931670636"/>
              <geom type="mesh" contype="0" conaffinity="0" group="1" rgba="1 1 1 1" name="f_visual" mesh="forearm_link" />
              <geom type="mesh" conaffinity="0" rgba="0.75294 0.75294 0.75294 1" mesh="forearm_link" name="f_collision"/>
              <body name="SphericalWrist1_Link" pos="0 -0.20843 -0.006375" quat="0.707105 -0.707108 0 0">
                <inertial pos="1e-06 -0.009432 -0.063883" quat="0.703558 0.0707492 -0.0707492 0.703558" mass="0.6781" diaginertia="0.00165901 0.001596 0.000346988" />
                <joint name="Actuator5" pos="0 0 0" axis="0 0 1" frictionloss="0.16110705026613545" damping="8.857224902652815" armature="8.466504091791412"/>
                <geom type="mesh" contype="0" conaffinity="0" group="1" rgba="1 1 1 1" name="w1_visual" mesh="spherical_wrist_1_link" />
                <geom type="mesh" conaffinity="0" rgba="0.75294 0.75294 0.75294 1" mesh="spherical_wrist_1_link" name="w1_collision"/>
                <body name="SphericalWrist2_Link" pos="0 0.00017505 -0.10593" quat="0.707105 0.707108 0 0">
                  <inertial pos="1e-06 -0.045483 -0.00965" quat="0.44426 0.550121 -0.550121 0.44426" mass="0.6781" diaginertia="0.00170087 0.001641 0.00035013" />
                  <joint name="Actuator6" pos="0 0 0" axis="0 0 1" limited="true" range="-2.23 2.23" frictionloss="0.13334911855141302" damping="8.711083156933284" armature="8.853706937374243"/>
                  <geom type="mesh" contype="0" conaffinity="0" group="1" rgba="1 1 1 1" name="w2_visual" mesh="spherical_wrist_2_link" />
                  <geom type="mesh" conaffinity="0" rgba="0.75294 0.75294 0.75294 1" mesh="spherical_wrist_2_link" name="w2_collision"/>
                  <body name="Bracelet_Link" pos="0 -0.10593 -0.00017505" quat="0.707105 -0.707108 0 0">
                    <inertial pos="0.000281 0.011402 -0.029798" mass="0.5" fullinertia="0.000587 0.000369 0.000609 3e-06 3e-06 -0.000118"/>
                    <joint name="Actuator7" pos="0 0 0" axis="0 0 1" frictionloss="0.143444018171737" damping="8.888190363830693" armature="8.858730366468532"/>
                    <geom type="mesh" contype="0" conaffinity="0" group="1" rgba="1 1 1 1" name="b_visual" mesh="bracelet_with_vision_link" />
                    <geom type="mesh" conaffinity="0" rgba="0.75294 0.75294 0.75294 1" mesh="bracelet_with_vision_link" name="b_collision"/>
                    <body name="gripper_base" pos="0 0 -0.065" quat="0 0.707105 -0.707108 0">
                      <inertial pos="6.91e-06 4.4117e-06 0.031656" quat="1 0 0 0" mass="0.60831" fullinertia="0.0004596 0.0005181 0.00036051 1.5559e-09 1.397e-07 -1.0325e-11"/>
                      <body name="waiter_tray_link" pos="0 -0.14948 0" euler="0 1.5707 0">
                        <inertial pos="0 -0.05717 0" mass="0.04394" fullinertia="0.00003615 0.00003615 0.00007225 0 0 0"/>
                        <body name="cube_link" pos="0 -0.0853 0.00127" euler="0 0 0">
                          <inertial pos="0 0 0.029" mass="0.1715" fullinertia="0.00007385 0.00007385 0.00007385 0 0 0"/>
                        </body>
                      </body>
                      <body name="gripper_right_spring_link" pos="0.0127 -0.061307 0" euler="3.1416 0 0.6983">
                        <inertial pos="-9.7222e-12 0.028253 6.791e-10" mass="0.029951" fullinertia="1.5103e-05 5.0789e-06 1.0707e-05 -1.0709e-16 -2.654e-15 3.2666e-14"/>
                        <!-- <joint name="Axis1" pos="0 0 0" axis="0 0 1"/> -->
                      </body>
                      <body name="gripper_right_driver" pos="0.030601 -0.054792 0" euler="3.1416 0 -0.019735">
                        <inertial pos="0.0179377478479594 0.000926031753317007 -4.0741034207454e-11" mass="0.0184906489409923" fullinertia="6.7944e-07 3.4593e-06 3.75009e-06 -2.07288e-07 5.46291e-15 7.55029e-15"/>
                        <!-- <joint name="Axis2" pos="0 0 0" axis="0 0 1"/> -->
                        <body name="gripper_right_coupler" pos="0.031486 -0.0040855 0" euler="0 0 -0.25804">
                          <inertial pos="-0.00277693278884095 0.0214010778170948 -2.64117771736162e-15" mass="0.0273093985570947" fullinertia="8.4351877262463e-06 2.33117687880373e-06 6.9133328065108e-06 8.05599897942411e-07 3.98563616297657e-19 -6.91949626399278e-19"/>
                          <!-- <joint name="Axis3" pos="0 0 0" axis="0 0 -1"/> -->
                          <body name="gripper_right_follower" pos="-0.0061148 0.047125 0" euler="3.1416 0 -2.9033">
                            <inertial pos="0.0118738800643238 0.013213950103123 -6.42371679073841e-16" mass="0.0195548943464751" fullinertia="3.99125345460037E-06 1.28831055431048E-06 4.59174098263665E-06 -9.32228708142781E-07 -1.06756339811242E-18 -9.53069862405573E-19"/>
                            <!-- <joint name="Axis2" pos="0 0 0" axis="0 0 1"/> -->
                            <body name="gripper_right_pad" pos="0.024903 0.032264 0" euler="3.1416 0 -1.5708">
                              <intertial pos="0.000197179990555962 0.003 -5.73415880070697E-15" mass="0.0112846745192962" fullinertia="4.84198905594698E-07 1.75287448520128E-06 1.33638362672235E-06 1.17467826101044E-22 -2.69493952498347E-22 3.01393554780919E-23"/>
                            </body>
                          </body>
                        </body>
                      </body>
                      <body name="gripper_left_spring_link" pos="-0.0127 -0.061307 0" euler="3.1416 0 -0.70092">
                        <inertial pos="-8.05421701555176E-13 0.0282525952540491 7.27854432947014E-10" mass="0.0299513316731757" fullinertia="1.51025275365861E-05 5.07891354120236E-06 1.0706817344978E-05 1.3893966137107E-16 -5.21047318848845E-15 3.47379370230503E-14"/>
                      </body>
                      <body name="gripper_left_driver" euler="0 0 -3.1245" pos="-0.030601 -0.054792 0">
                        <inertial pos="0.0179377478480944 0.000926031754016808 -4.09476305946672E-11" mass="0.0184906489414316" fullinertia="6.79440340033055E-07 3.45929623843939E-06 3.75009298156646E-06 -2.07287901659297E-07 5.48822371152932E-15 7.56200742857023E-15"/>
                        <body name="gripper_left_coupler" euler="3.1416 0 -3.1416" pos="0.031486 -0.0040855 0">
                          <inertial pos="-0.00277693278884093 0.0214010778170948 -2.65696393157366E-15" mass="0.0273093985570947" fullinertia="8.43518772624629E-06 2.33117687880373E-06 6.9133328065108E-06 8.05599897942414E-07 3.98028057558574E-19 -6.91715450328278E-19"/>
                          <body name="gripper_left_pad" euler="0 0 -1.5708" pos="0.018903 0.032265 0">
                            <inertial pos="-0.00277693278884093 0.0214010778170948 -2.65696393157366E-15" mass="0.0273093985570947" fullinertia="8.43518772624629E-06 2.33117687880373E-06 6.9133328065108E-06 8.05599897942414E-07 3.98028057558574E-19 -6.91715450328278E-19"/>
                          </body>
                        </body>
                      </body>
                    </body>
                  </body>
                </body>
              </body>
            </body>
          </body>
        </body>
      </body>
    </body>
  </worldbody>
</mujoco>
